Workbook

Sheet ANALYSIS_SUMMARY
A1: THE $30B LIFELINE: Understanding OFW Remittance Trends
A2: Analyze Phase — Key Findings Summary | BSP Cash Remittances by Country, 2019–2024
A3: Analyst: Lester John Taborda | Date: March 25, 2026
A5: 01 — DATA OVERVIEW
A6: Dataset | B6: Primary dataset: BSP Cash Remittances by Country (OFW Remittances), 2019–2024. Unit: USD Thousands. Source: Bangko Sentral ng Pilipinas (BSP), downloaded from the BSP Statistics Portal. Supplementary dataset: PSA Survey on Overseas Filipinos (SOF) 2024 — Remittance by Mode of Transfer. Covers national-level bank vs. non-bank usage rates.
A7: Scope | B7: 27 corridors included — all countries with annual remittance totals ≥ USD 100 million in 2024. Countries falling below this threshold in earlier years (Macao SAR, Switzerland) were excluded from the corridor list as they no longer represent strategically significant volumes. Countries entering the threshold mid-period (Israel, Liberia, Marshall Islands) are included with partial-year data; CAGR is marked N/A for these.
A8: Coverage Validation | B8: All 6 annual grand totals validated against BSP published figures prior to analysis. 2019: $30.13B | 2020: $29.90B | 2021: $31.42B | 2022: $32.54B | 2023: $33.49B | 2024: $34.49B (USD thousands). All figures match exactly. No imputation or estimation applied to source data.
A10: 02 — FINDING 1: US CORRIDOR DOMINANCE IS STRUCTURAL
A11: Key Insight | B11: The United States corridor is not merely the largest — it operates in a different category entirely. At USD 14.01B in 2024, it is 5.6x larger than #2 Singapore (USD 2.48B) and accounts for approximately 40.6% of all tracked OFW remittances. This share has been consistently above 37% across all six years, rising from 37.6% in 2019 to a peak of 41.2% in 2022 before stabilizing near 40.6%. Over the full 6-year period, the US corridor generated a cumulative USD 77.1B — more than the next five corridors combined.
A12: Rank | B12: Country | C12: 2024 Volume (USD 000s) | D12: 6-Yr Total (USD 000s)
A13: 1 | B13: United States of America | C13: 14013899 | D13: 77111110
A14: 2 | B14: Singapore | C14: 2481459 | D14: 13392001
A15: 3 | B15: Saudi Arabia | C15: 2219250 | D15: 11969598
A16: 4 | B16: Japan | C16: 1706720 | D16: 10019523
A17: 5 | B17: United Kingdom | C17: 1622046 | D17: 9154893
A19: 03 — FINDING 2: COVID CREATED A TALE OF TWO CORRIDORS
A20: Key Insight | B20: COVID-19 (2019→2020) did not uniformly reduce remittances — it exposed a structural divide. Western and maritime corridors (US +5.5%, Singapore +12.7%, Canada +1.3%, Hong Kong +2.4%, Taiwan +15.5%) grew or held steady, while Middle East labor corridors contracted sharply (Kuwait -23.5%, Bahrain -29.2%, UAE -19.2%, Saudi Arabia -13.7%). This reflects the different OFW profiles per corridor: professional/skilled workers in the West often shifted to remote work and maintained or increased income, while domestic and construction workers in the Gulf faced job losses and repatriation. Notably, Oman (+68.2%), Cyprus (+63.2%), Greece (+48.7%), and Panama (+45.2%) saw sharp spikes — likely driven by maritime OFWs, cargo shipping demand surges, and repatriation money transfers.
A21: Recovery Pattern | B21: Middle East corridors largely recovered by 2022–2023, driven by oil price recovery and re-hiring. Saudi Arabia returned to above-2019 levels by 2023 ($2.06B vs $2.10B in 2019) and reached $2.22B in 2024. UAE and Kuwait have not yet returned to 2019 levels as of 2024, suggesting structural workforce reduction in those markets post-COVID. Western corridors continued growing uninterrupted throughout.
A23: 04 — FINDING 3: EMERGING HIGH-GROWTH CORRIDORS
A24: Key Insight | B24: Several mid-tier corridors are growing faster than top-volume corridors, signaling shifting OFW deployment. Cyprus (CAGR +14.9%), Greece (CAGR +14.7%), and Panama (CAGR +13.9%) lead growth — all maritime-linked. Taiwan, Republic of China (+9.7%) and Malaysia (+7.2%) show strong land-based growth, driven by manufacturing and services OFW deployment. These corridors are small in absolute volume today but represent the pipeline of future high-volume corridors — an early-mover opportunity for a bank establishing digital remittance infrastructure now.
A25: Country | B25: CAGR 2019–2024 | C25: 2019 Volume | D25: 2024 Volume
A26: Cyprus | B26: 14.90% | C26: 196902 | D26: 394866
A27: Greece | B27: 14.7% | C27: 152742 | D27: 302922
A28: Panama | B28: 13.9% | C28: 177098 | D28: 339737
A29: Taiwan, Republic of China | B29: 9.7% | C29: 597628 | D29: 948248
A30: Malaysia | B30: 7.2% | C30: 466775 | D30: 661182
A32: 05 — FINDING 4: $13.04B UNDERSERVED MARKET OPPORTUNITY
A33: Key Insight | B33: Applying PSA SOF 2024's national bank usage rate of 61%, an estimated 39% of OFW remittances flow through non-bank channels (money transfer operators, door-to-door, informal couriers). Across all 27 corridors using 2024 volumes as the basis, this represents approximately USD 13.04 billion annually in remittances not captured by formal banking infrastructure. The US corridor alone accounts for USD 5.47B of this — 41.9% of total non-bank estimated volume. This is the direct addressable market for a Philippine commercial bank's digital remittance expansion.
A34: Rank | B34: Country | C34: Non-Bank Est. (USD B) | D34: % of Total Opp.
A35: 1 | B35: United States of America | C35: 5.47 | D35: 0.419
A36: 2 | B36: Singapore | C36: 0.97 | D36: 0.074
A37: 3 | B37: Saudi Arabia | C37: 0.87 | D37: 0.066
A38: 4 | B38: Japan | C38: 0.67 | D38: 0.051
A39: 5 | B39: United Kingdom | C39: 0.63 | D39: 0.049
A40: TOTAL (all 27 corridors) | C40: 13.04 | D40: 1
A41: Limitation: 39% non-bank rate applied uniformly as a national proxy. Actual rates likely vary by corridor — Gulf corridors may skew higher (more informal), Western corridors may skew lower (more banked populations). Treat as order-of-magnitude estimate, not precise corridor-level measurement.
A43: 06 — KEY NOTES
A44: PSA mode proxy limitation | B44: 61% bank usage rate is national-level only. No corridor-level mode data exists in PSA SOF. Non-bank estimates are proxies — state as limitation in final report.
A45: Partial-year corridors (3 countries) | B45: Israel, Liberia, Marshall Islands have zero values in early years (below threshold). Included with partial data. Their CAGR and early YoY figures are N/A — this is correct, not an error.
A46: Macao SAR & Switzerland excluded | B46: Present in 2019 but dropped below $100M threshold by 2020. Excluded from the 27-country list. Documented in cleaning log. Available in BSP_CORRIDORS raw tab if needed.
...

Sheet ANALYSIS
A1: BSP OFW Remittance - Corridor Analysis | Unit: USD Thousands
A3: Country | B3: 2019 | C3: 2020 | D3: 2021 | E3: 2022 | F3: 2023 | G3: 2024 | H3: 6YR_Total | I3: CAGR_2019_2024 | J3: YoY_2019_2020 | K3: YoY_2020_2021 | L3: YoY_2021_2022 | M3: YoY_2022_2023 | N3: YoY_2023_2024 | O3: Share_2019 | P3: Share_2020 | Q3: Share_2021 | R3: Share_2022 | S3: Share_2023 | T3: Share_2024 | U3: Nonbank_Est_USD_000s | V3: Nonbank_Est_USD_Billions
A4: Australia | B4: =SUMIFS(BSP_CORRIDORS!$D:$D,BSP_CORRIDORS!$A:$A,B$3,BSP_CORRIDORS!$C:$C,$A4) -> 442309 | C4: =SUMIFS(BSP_CORRIDORS!$D:$D,BSP_CORRIDORS!$A:$A,C$3,BSP_CORRIDORS!$C:$C,$A4) -> 319129 | D4: =SUMIFS(BSP_CORRIDORS!$D:$D,BSP_CORRIDORS!$A:$A,D$3,BSP_CORRIDORS!$C:$C,$A4) -> 284924 | E4: =SUMIFS(BSP_CORRIDORS!$D:$D,BSP_CORRIDORS!$A:$A,E$3,BSP_CORRIDORS!$C:$C,$A4) -> 291794 | F4: =SUMIFS(BSP_CORRIDORS!$D:$D,BSP_CORRIDORS!$A:$A,F$3,BSP_CORRIDORS!$C:$C,$A4) -> 301261 | G4: =SUMIFS(BSP_CORRIDORS!$D:$D,BSP_CORRIDORS!$A:$A,G$3,BSP_CORRIDORS!$C:$C,$A4) -> 307064 | H4: =SUM(B4:G4) -> 1946481 | I4: =IF(B4=0,"N/A",(G4/B4)^(1/5)-1) -> -0.070390346 | J4: =IF(B4=0,"N/A",(C4-B4)/B4) -> -0.27849309 | K4: =IF(C4=0,"N/A",(D4-C4)/C4) -> -0.10718236 | L4: =IF(D4=0,"N/A",(E4-D4)/D4) -> 0.024111693 | M4: =IF(E4=0,"N/A",(F4-E4)/E4) -> 0.032444122 | N4: =IF(F4=0,"N/A/",(G4-F4)/F4) -> 0.019262367 | O4: =IF(B4=0,"N/A",B4/30133300) -> 0.014678412 | P4: =IF(C4=0,"N/A",C4/29903256) -> 0.010672049 | Q4: =IF(D4=0,"N/A",D4/31417614) -> 0.0090689255 | R4: =IF(E4=0,"N/A",E4/32539430) -> 0.0089673974 | S4: =IF(F4=0,"N/A",F4/33490930) -> 0.0089953011 | T4: =IF(G4=0,"N/A",G4/34492616) -> 0.0089023111 | U4: =IF(G4=0,"N/A",G4*0.39) -> 119754.96 | V4: =IF(U4="N/A","N/A",U4/1000000) -> 0.11975496
A5: Bahrain | B5: =SUMIFS(BSP_CORRIDORS!$D:$D,BSP_CORRIDORS!$A:$A,B$3,BSP_CORRIDORS!$C:$C,$A5) -> 323033 | C5: =SUMIFS(BSP_CORRIDORS!$D:$D,BSP_CORRIDORS!$A:$A,C$3,BSP_CORRIDORS!$C:$C,$A5) -> 228554 | D5: =SUMIFS(BSP_CORRIDORS!$D:$D,BSP_CORRIDORS!$A:$A,D$3,BSP_CORRIDORS!$C:$C,$A5) -> 225890 | E5: =SUMIFS(BSP_CORRIDORS!$D:$D,BSP_CORRIDORS!$A:$A,E$3,BSP_CORRIDORS!$C:$C,$A5) -> 244904 | F5: =SUMIFS(BSP_CORRIDORS!$D:$D,BSP_CORRIDORS!$A:$A,F$3,BSP_CORRIDORS!$C:$C,$A5) -> 254996 | G5: =SUMIFS(BSP_CORRIDORS!$D:$D,BSP_CORRIDORS!$A:$A,G$3,BSP_CORRIDORS!$C:$C,$A5) -> 261458 | H5: =SUM(B5:G5) -> 1538835 | I5: =IF(B5=0,"N/A",(G5/B5)^(1/5)-1) -> -0.041414161 | J5: =IF(B5=0,"N/A",(C5-B5)/B5) -> -0.29247476 | K5: =IF(C5=0,"N/A",(D5-C5)/C5) -> -0.011655889 | L5: =IF(D5=0,"N/A",(E5-D5)/D5) -> 0.084173713 | M5: =IF(E5=0,"N/A",(F5-E5)/E5) -> 0.041207984 | N5: =IF(F5=0,"N/A/",(G5-F5)/F5) -> 0.025341574 | O5: =IF(B5=0,"N/A",B5/30133300) -> 0.010720134 | P5: =IF(C5=0,"N/A",C5/29903256) -> 0.0076431142 | Q5: =IF(D5=0,"N/A",D5/31417614) -> 0.0071899158 | R5: =IF(E5=0,"N/A",E5/32539430) -> 0.0075263765 | S5: =IF(F5=0,"N/A",F5/33490930) -> 0.0076138823 | T5: =IF(G5=0,"N/A",G5/34492616) -> 0.0075801151 | U5: =IF(G5=0,"N/A",G5*0.39) -> 101968.62 | V5: =IF(U5="N/A","N/A",U5/1000000) -> 0.10196862
A6: Canada | B6: =SUMIFS(BSP_CORRIDORS!$D:$D,BSP_CORRIDORS!$A:$A,B$3,BSP_CORRIDORS!$C:$C,$A6) -> 1015805 | C6: =SUMIFS(BSP_CORRIDORS!$D:$D,BSP_CORRIDORS!$A:$A,C$3,BSP_CORRIDORS!$C:$C,$A6) -> 1028866 | D6: =SUMIFS(BSP_CORRIDORS!$D:$D,BSP_CORRIDORS!$A:$A,D$3,BSP_CORRIDORS!$C:$C,$A6) -> 1147796 | E6: =SUMIFS(BSP_CORRIDORS!$D:$D,BSP_CORRIDORS!$A:$A,E$3,BSP_CORRIDORS!$C:$C,$A6) -> 1172530 | F6: =SUMIFS(BSP_CORRIDORS!$D:$D,BSP_CORRIDORS!$A:$A,F$3,BSP_CORRIDORS!$C:$C,$A6) -> 1208259 | G6: =SUMIFS(BSP_CORRIDORS!$D:$D,BSP_CORRIDORS!$A:$A,G$3,BSP_CORRIDORS!$C:$C,$A6) -> 1230773 | H6: =SUM(B6:G6) -> 6804029 | I6: =IF(B6=0,"N/A",(G6/B6)^(1/5)-1) -> 0.039138709 | J6: =IF(B6=0,"N/A",(C6-B6)/B6) -> 0.012857783 | K6: =IF(C6=0,"N/A",(D6-C6)/C6) -> 0.11559328 | L6: =IF(D6=0,"N/A",(E6-D6)/D6) -> 0.021549125 | M6: =IF(E6=0,"N/A",(F6-E6)/E6) -> 0.030471715 | N6: =IF(F6=0,"N/A/",(G6-F6)/F6) -> 0.018633422 | O6: =IF(B6=0,"N/A",B6/30133300) -> 0.03371038 | P6: =IF(C6=0,"N/A",C6/29903256) -> 0.034406487 | Q6: =IF(D6=0,"N/A",D6/31417614) -> 0.036533519 | R6: =IF(E6=0,"N/A",E6/32539430) -> 0.036034128 | S6: =IF(F6=0,"N/A",F6/33490930) -> 0.036077201 | T6: =IF(G6=0,"N/A",G6/34492616) -> 0.035682217 | U6: =IF(G6=0,"N/A",G6*0.39) -> 480001.47 | V6: =IF(U6="N/A","N/A",U6/1000000) -> 0.48000147
A7: Cyprus | B7: =SUMIFS(BSP_CORRIDORS!$D:$D,BSP_CORRIDORS!$A:$A,B$3,BSP_CORRIDORS!$C:$C,$A7) -> 196902 | C7: =SUMIFS(BSP_CORRIDORS!$D:$D,BSP_CORRIDORS!$A:$A,C$3,BSP_CORRIDORS!$C:$C,$A7) -> 321256 | D7: =SUMIFS(BSP_CORRIDORS!$D:$D,BSP_CORRIDORS!$A:$A,D$3,BSP_CORRIDORS!$C:$C,$A7) -> 364133 | E7: =SUMIFS(BSP_CORRIDORS!$D:$D,BSP_CORRIDORS!$A:$A,E$3,BSP_CORRIDORS!$C:$C,$A7) -> 384391 | F7: =SUMIFS(BSP_CORRIDORS!$D:$D,BSP_CORRIDORS!$A:$A,F$3,BSP_CORRIDORS!$C:$C,$A7) -> 391768 | G7: =SUMIFS(BSP_CORRIDORS!$D:$D,BSP_CORRIDORS!$A:$A,G$3,BSP_CORRIDORS!$C:$C,$A7) -> 394866 | H7: =SUM(B7:G7) -> 2053316 | I7: =IF(B7=0,"N/A",(G7/B7)^(1/5)-1) -> 0.14931724 | J7: =IF(B7=0,"N/A",(C7-B7)/B7) -> 0.63155275 | K7: =IF(C7=0,"N/A",(D7-C7)/C7) -> 0.13346677 | L7: =IF(D7=0,"N/A",(E7-D7)/D7) -> 0.055633519 | M7: =IF(E7=0,"N/A",(F7-E7)/E7) -> 0.019191396 | N7: =IF(F7=0,"N/A/",(G7-F7)/F7) -> 0.0079077413 | O7: =IF(B7=0,"N/A",B7/30133300) -> 0.0065343656 | P7: =IF(C7=0,"N/A",C7/29903256) -> 0.010743178 | Q7: =IF(D7=0,"N/A",D7/31417614) -> 0.011590091 | R7: =IF(E7=0,"N/A",E7/32539430) -> 0.011813083 | S7: =IF(F7=0,"N/A",F7/33490930) -> 0.011697734 | T7: =IF(G7=0,"N/A",G7/34492616) -> 0.011447841 | U7: =IF(G7=0,"N/A",G7*0.39) -> 153997.74 | V7: =IF(U7="N/A","N/A",U7/1000000) -> 0.15399774
A8: Germany | B8: =SUMIFS(BSP_CORRIDORS!$D:$D,BSP_CORRIDORS!$A:$A,B$3,BSP_CORRIDORS!$C:$C,$A8) -> 762304 | C8: =SUMIFS(BSP_CORRIDORS!$D:$D,BSP_CORRIDORS!$A:$A,C$3,BSP_CORRIDORS!$C:$C,$A8) -> 585962 | D8: =SUMIFS(BSP_CORRIDORS!$D:$D,BSP_CORRIDORS!$A:$A,D$3,BSP_CORRIDORS!$C:$C,$A8) -> 609108 | E8: =SUMIFS(BSP_CORRIDORS!$D:$D,BSP_CORRIDORS!$A:$A,E$3,BSP_CORRIDORS!$C:$C,$A8) -> 592543 | F8: =SUMIFS(BSP_CORRIDORS!$D:$D,BSP_CORRIDORS!$A:$A,F$3,BSP_CORRIDORS!$C:$C,$A8) -> 607552 | G8: =SUMIFS(BSP_CORRIDORS!$D:$D,BSP_CORRIDORS!$A:$A,G$3,BSP_CORRIDORS!$C:$C,$A8) -> 622561 | H8: =SUM(B8:G8) -> 3780030 | I8: =IF(B8=0,"N/A",(G8/B8)^(1/5)-1) -> -0.039691567 | J8: =IF(B8=0,"N/A",(C8-B8)/B8) -> -0.23132766 | K8: =IF(C8=0,"N/A",(D8-C8)/C8) -> 0.039500855 | L8: =IF(D8=0,"N/A",(E8-D8)/D8) -> -0.027195506 | M8: =IF(E8=0,"N/A",(F8-E8)/E8) -> 0.025329807 | N8: =IF(F8=0,"N/A/",(G8-F8)/F8) -> 0.024704058 | O8: =IF(B8=0,"N/A",B8/30133300) -> 0.025297727 | P8: =IF(C8=0,"N/A",C8/29903256) -> 0.019595257 | Q8: =IF(D8=0,"N/A",D8/31417614) -> 0.019387468 | R8: =IF(E8=0,"N/A",E8/32539430) -> 0.018209999 | S8: =IF(F8=0,"N/A",F8/33490930) -> 0.018140792 | T8: =IF(G8=0,"N/A",G8/34492616) -> 0.018049109 | U8: =IF(G8=0,"N/A",G8*0.39) -> 242798.79 | V8: =IF(U8="N/A","N/A",U8/1000000) -> 0.24279879
A9: Greece | B9: =SUMIFS(BSP_CORRIDORS!$D:$D,BSP_CORRIDORS!$A:$A,B$3,BSP_CORRIDORS!$C:$C,$A9) -> 152742 | C9: =SUMIFS(BSP_CORRIDORS!$D:$D,BSP_CORRIDORS!$A:$A,C$3,BSP_CORRIDORS!$C:$C,$A9) -> 227187 | D9: =SUMIFS(BSP_CORRIDORS!$D:$D,BSP_CORRIDORS!$A:$A,D$3,BSP_CORRIDORS!$C:$C,$A9) -> 296023 | E9: =SUMIFS(BSP_CORRIDORS!$D:$D,BSP_CORRIDORS!$A:$A,E$3,BSP_CORRIDORS!$C:$C,$A9) -> 289307 | F9: =SUMIFS(BSP_CORRIDORS!$D:$D,BSP_CORRIDORS!$A:$A,F$3,BSP_CORRIDORS!$C:$C,$A9) -> 296638 | G9: =SUMIFS(BSP_CORRIDORS!$D:$D,BSP_CORRIDORS!$A:$A,G$3,BSP_CORRIDORS!$C:$C,$A9) -> 302922 | H9: =SUM(B9:G9) -> 1564819 | I9: =IF(B9=0,"N/A",(G9/B9)^(1/5)-1) -> 0.1467651 | J9: =IF(B9=0,"N/A",(C9-B9)/B9) -> 0.4873905 | K9: =IF(C9=0,"N/A",(D9-C9)/C9) -> 0.30299269 | L9: =IF(D9=0,"N/A",(E9-D9)/D9) -> -0.022687426 | M9: =IF(E9=0,"N/A",(F9-E9)/E9) -> 0.025339864 | N9: =IF(F9=0,"N/A/",(G9-F9)/F9) -> 0.021184069 | O9: =IF(B9=0,"N/A",B9/30133300) -> 0.0050688773 | P9: =IF(C9=0,"N/A",C9/29903256) -> 0.0075974001 | Q9: =IF(D9=0,"N/A",D9/31417614) -> 0.0094221986 | R9: =IF(E9=0,"N/A",E9/32539430) -> 0.0088909671 | S9: =IF(F9=0,"N/A",F9/33490930) -> 0.0088572637 | T9: =IF(G9=0,"N/A",G9/34492616) -> 0.0087822275 | U9: =IF(G9=0,"N/A",G9*0.39) -> 118139.58 | V9: =IF(U9="N/A","N/A",U9/1000000) -> 0.11813958
A10: Hong Kong, SAR China | B10: =SUMIFS(BSP_CORRIDORS!$D:$D,BSP_CORRIDORS!$A:$A,B$3,BSP_CORRIDORS!$C:$C,$A10) -> 801749 | C10: =SUMIFS(BSP_CORRIDORS!$D:$D,BSP_CORRIDORS!$A:$A,C$3,BSP_CORRIDORS!$C:$C,$A10) -> 821160 | D10: =SUMIFS(BSP_CORRIDORS!$D:$D,BSP_CORRIDORS!$A:$A,D$3,BSP_CORRIDORS!$C:$C,$A10) -> 722229 | E10: =SUMIFS(BSP_CORRIDORS!$D:$D,BSP_CORRIDORS!$A:$A,E$3,BSP_CORRIDORS!$C:$C,$A10) -> 732360 | F10: =SUMIFS(BSP_CORRIDORS!$D:$D,BSP_CORRIDORS!$A:$A,F$3,BSP_CORRIDORS!$C:$C,$A10) -> 764302 | G10: =SUMIFS(BSP_CORRIDORS!$D:$D,BSP_CORRIDORS!$A:$A,G$3,BSP_CORRIDORS!$C:$C,$A10) -> 801831 | H10: =SUM(B10:G10) -> 4643631 | I10: =IF(B10=0,"N/A",(G10/B10)^(1/5)-1) -> 2.0454443e-05 | J10: =IF(B10=0,"N/A",(C10-B10)/B10) -> 0.024210819 | K10: =IF(C10=0,"N/A",(D10-C10)/C10) -> -0.12047713 | L10: =IF(D10=0,"N/A",(E10-D10)/D10) -> 0.014027407 | M10: =IF(E10=0,"N/A",(F10-E10)/E10) -> 0.043615162 | N10: =IF(F10=0,"N/A/",(G10-F10)/F10) -> 0.049102318 | O10: =IF(B10=0,"N/A",B10/30133300) -> 0.026606744 | P10: =IF(C10=0,"N/A",C10/29903256) -> 0.027460555 | Q10: =IF(D10=0,"N/A",D10/31417614) -> 0.022988028 | R10: =IF(E10=0,"N/A",E10/32539430) -> 0.022506848 | S10: =IF(F10=0,"N/A",F10/33490930) -> 0.022821164 | T10: =IF(G10=0,"N/A",G10/34492616) -> 0.023246454 | U10: =IF(G10=0,"N/A",G10*0.39) -> 312714.09 | V10: =IF(U10="N/A","N/A",U10/1000000) -> 0.31271409
A11: Israel | B11: =SUMIFS(BSP_CORRIDORS!$D:$D,BSP_CORRIDORS!$A:$A,B$3,BSP_CORRIDORS!$C:$C,$A11) -> 0 | C11: =SUMIFS(BSP_CORRIDORS!$D:$D,BSP_CORRIDORS!$A:$A,C$3,BSP_CORRIDORS!$C:$C,$A11) -> 0 | D11: =SUMIFS(BSP_CORRIDORS!$D:$D,BSP_CORRIDORS!$A:$A,D$3,BSP_CORRIDORS!$C:$C,$A11) -> 119837 | E11: =SUMIFS(BSP_CORRIDORS!$D:$D,BSP_CORRIDORS!$A:$A,E$3,BSP_CORRIDORS!$C:$C,$A11) -> 110602 | F11: =SUMIFS(BSP_CORRIDORS!$D:$D,BSP_CORRIDORS!$A:$A,F$3,BSP_CORRIDORS!$C:$C,$A11) -> 109136 | G11: =SUMIFS(BSP_CORRIDORS!$D:$D,BSP_CORRIDORS!$A:$A,G$3,BSP_CORRIDORS!$C:$C,$A11) -> 106411 | H11: =SUM(B11:G11) -> 445986 | I11: =IF(B11=0,"N/A",(G11/B11)^(1/5)-1) -> N/A | J11: =IF(B11=0,"N/A",(C11-B11)/B11) -> N/A | K11: =IF(C11=0,"N/A",(D11-C11)/C11) -> N/A | L11: =IF(D11=0,"N/A",(E11-D11)/D11) -> -0.077063011 | M11: =IF(E11=0,"N/A",(F11-E11)/E11) -> -0.013254733 | N11: =IF(F11=0,"N/A/",(G11-F11)/F11) -> -0.024968846 | O11: =IF(B11=0,"N/A",B11/30133300) -> N/A | P11: =IF(C11=0,"N/A",C11/29903256) -> N/A | Q11: =IF(D11=0,"N/A",D11/31417614) -> 0.0038143253 | R11: =IF(E11=0,"N/A",E11/32539430) -> 0.0033990147 | S11: =IF(F11=0,"N/A",F11/33490930) -> 0.0032586733 | T11: =IF(G11=0,"N/A",G11/34492616) -> 0.0030850371 | U11: =IF(G11=0,"N/A",G11*0.39) -> 41500.29 | V11: =IF(U11="N/A","N/A",U11/1000000) -> 0.04150029
A12: Italy | B12: =SUMIFS(BSP_CORRIDORS!$D:$D,BSP_CORRIDORS!$A:$A,B$3,BSP_CORRIDORS!$C:$C,$A12) -> 217405 | C12: =SUMIFS(BSP_CORRIDORS!$D:$D,BSP_CORRIDORS!$A:$A,C$3,BSP_CORRIDORS!$C:$C,$A12) -> 179367 | D12: =SUMIFS(BSP_CORRIDORS!$D:$D,BSP_CORRIDORS!$A:$A,D$3,BSP_CORRIDORS!$C:$C,$A12) -> 164366 | E12: =SUMIFS(BSP_CORRIDORS!$D:$D,BSP_CORRIDORS!$A:$A,E$3,BSP_CORRIDORS!$C:$C,$A12) -> 151525 | F12: =SUMIFS(BSP_CORRIDORS!$D:$D,BSP_CORRIDORS!$A:$A,F$3,BSP_CORRIDORS!$C:$C,$A12) -> 154189 | G12: =SUMIFS(BSP_CORRIDORS!$D:$D,BSP_CORRIDORS!$A:$A,G$3,BSP_CORRIDORS!$C:$C,$A12) -> 155782 | H12: =SUM(B12:G12) -> 1022634 | I12: =IF(B12=0,"N/A",(G12/B12)^(1/5)-1) -> -0.064487598 | J12: =IF(B12=0,"N/A",(C12-B12)/B12) -> -0.17496378 | K12: =IF(C12=0,"N/A",(D12-C12)/C12) -> -0.083632998 | L12: =IF(D12=0,"N/A",(E12-D12)/D12) -> -0.07812443 | M12: =IF(E12=0,"N/A",(F12-E12)/E12) -> 0.017581257 | N12: =IF(F12=0,"N/A/",(G12-F12)/F12) -> 0.010331476 | O12: =IF(B12=0,"N/A",B12/30133300) -> 0.0072147757 | P12: =IF(C12=0,"N/A",C12/29903256) -> 0.0059982431 | Q12: =IF(D12=0,"N/A",D12/31417614) -> 0.0052316513 | R12: =IF(E12=0,"N/A",E12/32539430) -> 0.0046566581 | S12: =IF(F12=0,"N/A",F12/33490930) -> 0.0046039032 | T12: =IF(G12=0,"N/A",G12/34492616) -> 0.0045163869 | U12: =IF(G12=0,"N/A",G12*0.39) -> 60754.98 | V12: =IF(U12="N/A","N/A",U12/1000000) -> 0.06075498
A13: Japan | B13: =SUMIFS(BSP_CORRIDORS!$D:$D,BSP_CORRIDORS!$A:$A,B$3,BSP_CORRIDORS!$C:$C,$A13) -> 1795383 | C13: =SUMIFS(BSP_CORRIDORS!$D:$D,BSP_CORRIDORS!$A:$A,C$3,BSP_CORRIDORS!$C:$C,$A13) -> 1576557 | D13: =SUMIFS(BSP_CORRIDORS!$D:$D,BSP_CORRIDORS!$A:$A,D$3,BSP_CORRIDORS!$C:$C,$A13) -> 1611196 | E13: =SUMIFS(BSP_CORRIDORS!$D:$D,BSP_CORRIDORS!$A:$A,E$3,BSP_CORRIDORS!$C:$C,$A13) -> 1644737 | F13: =SUMIFS(BSP_CORRIDORS!$D:$D,BSP_CORRIDORS!$A:$A,F$3,BSP_CORRIDORS!$C:$C,$A13) -> 1684930 | G13: =SUMIFS(BSP_CORRIDORS!$D:$D,BSP_CORRIDORS!$A:$A,G$3,BSP_CORRIDORS!$C:$C,$A13) -> 1706720 | H13: =SUM(B13:G13) -> 10019523 | I13: =IF(B13=0,"N/A",(G13/B13)^(1/5)-1) -> -0.010077868 | J13: =IF(B13=0,"N/A",(C13-B13)/B13) -> -0.12188263 | K13: =IF(C13=0,"N/A",(D13-C13)/C13) -> 0.021971296 | L13: =IF(D13=0,"N/A",(E13-D13)/D13) -> 0.020817455 | M13: =IF(E13=0,"N/A",(F13-E13)/E13) -> 0.024437342 | N13: =IF(F13=0,"N/A/",(G13-F13)/F13) -> 0.012932288 | O13: =IF(B13=0,"N/A",B13/30133300) -> 0.05958136 | P13: =IF(C13=0,"N/A",C13/29903256) -> 0.052721918 | Q13: =IF(D13=0,"N/A",D13/31417614) -> 0.051283207 | R13: =IF(E13=0,"N/A",E13/32539430) -> 0.050545968 | S13: =IF(F13=0,"N/A",F13/33490930) -> 0.050310039 | T13: =IF(G13=0,"N/A",G13/34492616) -> 0.049480735 | U13: =IF(G13=0,"N/A",G13*0.39) -> 665620.8 | V13: =IF(U13="N/A","N/A",U13/1000000) -> 0.6656208
A14: Korea (South) | B14: =SUMIFS(BSP_CORRIDORS!$D:$D,BSP_CORRIDORS!$A:$A,B$3,BSP_CORRIDORS!$C:$C,$A14) -> 683211 | C14: =SUMIFS(BSP_CORRIDORS!$D:$D,BSP_CORRIDORS!$A:$A,C$3,BSP_CORRIDORS!$C:$C,$A14) -> 707635 | D14: =SUMIFS(BSP_CORRIDORS!$D:$D,BSP_CORRIDORS!$A:$A,D$3,BSP_CORRIDORS!$C:$C,$A14) -> 788166 | E14: =SUMIFS(BSP_CORRIDORS!$D:$D,BSP_CORRIDORS!$A:$A,E$3,BSP_CORRIDORS!$C:$C,$A14) -> 811729 | F14: =SUMIFS(BSP_CORRIDORS!$D:$D,BSP_CORRIDORS!$A:$A,F$3,BSP_CORRIDORS!$C:$C,$A14) -> 834749 | G14: =SUMIFS(BSP_CORRIDORS!$D:$D,BSP_CORRIDORS!$A:$A,G$3,BSP_CORRIDORS!$C:$C,$A14) -> 853749 | H14: =SUM(B14:G14) -> 4679239 | I14: =IF(B14=0,"N/A",(G14/B14)^(1/5)-1) -> 0.045574713 | J14: =IF(B14=0,"N/A",(C14-B14)/B14) -> 0.035748839 | K14: =IF(C14=0,"N/A",(D14-C14)/C14) -> 0.11380302 | L14: =IF(D14=0,"N/A",(E14-D14)/D14) -> 0.029895986 | M14: =IF(E14=0,"N/A",(F14-E14)/E14) -> 0.028359218 | N14: =IF(F14=0,"N/A/",(G14-F14)/F14) -> 0.022761333 | O14: =IF(B14=0,"N/A",B14/30133300) -> 0.022672956 | P14: =IF(C14=0,"N/A",C14/29903256) -> 0.023664145 | Q14: =IF(D14=0,"N/A",D14/31417614) -> 0.025086755 | R14: =IF(E14=0,"N/A",E14/32539430) -> 0.024946012 | S14: =IF(F14=0,"N/A",F14/33490930) -> 0.024924629 | T14: =IF(G14=0,"N/A",G14/34492616) -> 0.024751645 | U14: =IF(G14=0,"N/A",G14*0.39) -> 332962.11 | V14: =IF(U14="N/A","N/A",U14/1000000) -> 0.33296211
A15: Kuwait | B15: =SUMIFS(BSP_CORRIDORS!$D:$D,BSP_CORRIDORS!$A:$A,B$3,BSP_CORRIDORS!$C:$C,$A15) -> 759081 | C15: =SUMIFS(BSP_CORRIDORS!$D:$D,BSP_CORRIDORS!$A:$A,C$3,BSP_CORRIDORS!$C:$C,$A15) -> 580625 | D15: =SUMIFS(BSP_CORRIDORS!$D:$D,BSP_CORRIDORS!$A:$A,D$3,BSP_CORRIDORS!$C:$C,$A15) -> 576059 | E15: =SUMIFS(BSP_CORRIDORS!$D:$D,BSP_CORRIDORS!$A:$A,E$3,BSP_CORRIDORS!$C:$C,$A15) -> 597186 | F15: =SUMIFS(BSP_CORRIDORS!$D:$D,BSP_CORRIDORS!$A:$A,F$3,BSP_CORRIDORS!$C:$C,$A15) -> 585172 | G15: =SUMIFS(BSP_CORRIDORS!$D:$D,BSP_CORRIDORS!$A:$A,G$3,BSP_CORRIDORS!$C:$C,$A15) -> 587166 | H15: =SUM(B15:G15) -> 3685289 | I15: =IF(B15=0,"N/A",(G15/B15)^(1/5)-1) -> -0.050063543 | J15: =IF(B15=0,"N/A",(C15-B15)/B15) -> -0.23509481 | K15: =IF(C15=0,"N/A",(D15-C15)/C15) -> -0.0078639397 | L15: =IF(D15=0,"N/A",(E15-D15)/D15) -> 0.036675063 | M15: =IF(E15=0,"N/A",(F15-E15)/E15) -> -0.020117685 | N15: =IF(F15=0,"N/A/",(G15-F15)/F15) -> 0.0034075451 | O15: =IF(B15=0,"N/A",B15/30133300) -> 0.025190769 | P15: =IF(C15=0,"N/A",C15/29903256) -> 0.019416782 | Q15: =IF(D15=0,"N/A",D15/31417614) -> 0.018335543 | R15: =IF(E15=0,"N/A",E15/32539430) -> 0.018352688 | S15: =IF(F15=0,"N/A",F15/33490930) -> 0.017472552 | T15: =IF(G15=0,"N/A",G15/34492616) -> 0.017022948 | U15: =IF(G15=0,"N/A",G15*0.39) -> 228994.74 | V15: =IF(U15="N/A","N/A",U15/1000000) -> 0.22899474
... A30: United States of America | B30: =SUMIFS(BSP_CORRIDORS!$D:$D,BSP_CORRIDORS!$A:$A,B$3,BSP_CORRIDORS!$C:$C,$A30) -> 11318335 | C30: =SUMIFS(BSP_CORRIDORS!$D:$D,BSP_CORRIDORS!$A:$A,C$3,BSP_CORRIDORS!$C:$C,$A30) -> 11936353 | D30: =SUMIFS(BSP_CORRIDORS!$D:$D,BSP_CORRIDORS!$A:$A,D$3,BSP_CORRIDORS!$C:$C,$A30) -> 12735977 | E30: =SUMIFS(BSP_CORRIDORS!$D:$D,BSP_CORRIDORS!$A:$A,E$3,BSP_CORRIDORS!$C:$C,$A30) -> 13396567 | F30: =SUMIFS(BSP_CORRIDORS!$D:$D,BSP_CORRIDORS!$A:$A,F$3,BSP_CORRIDORS!$C:$C,$A30) -> 13709979 | G30: =SUMIFS(BSP_CORRIDORS!$D:$D,BSP_CORRIDORS!$A:$A,G$3,BSP_CORRIDORS!$C:$C,$A30) -> 14013899 | H30: =SUM(B30:G30) -> 77111110 | I30: =IF(B30=0,"N/A",(G30/B30)^(1/5)-1) -> 0.043650986 | J30: =IF(B30=0,"N/A",(C30-B30)/B30) -> 0.054603261 | K30: =IF(C30=0,"N/A",(D30-C30)/C30) -> 0.066990646 | L30: =IF(D30=0,"N/A",(E30-D30)/D30) -> 0.051868027 | M30: =IF(E30=0,"N/A",(F30-E30)/E30) -> 0.023394949 | N30: =IF(F30=0,"N/A/",(G30-F30)/F30) -> 0.022167795 | O30: =IF(B30=0,"N/A",B30/30133300) -> 0.37560888 | P30: =IF(C30=0,"N/A",C30/29903256) -> 0.39916566 | Q30: =IF(D30=0,"N/A",D30/31417614) -> 0.40537696 | R30: =IF(E30=0,"N/A",E30/32539430) -> 0.41170257 | S30: =IF(F30=0,"N/A",F30/33490930) -> 0.40936394 | T30: =IF(G30=0,"N/A",G30/34492616) -> 0.40628693 | U30: =IF(G30=0,"N/A",G30*0.39) -> 5465420.6 | V30: =IF(U30="N/A","N/A",U30/1000000) -> 5.4654206
V31: =SUM(V4:V30) -> 13.035154
A32: Note: Non-bank estimate applies 39% informal rate (PSA SOF 2024: 61% bank usage nationally) uniformly across corridors as proxy. Actual rates may vary by corridor.

Sheet ANALYSIS_LOG
A1: Analysis Log
A2: This log documents every consideration made during the Analyze phase. It feeds directly into Deliverable 4 (Summary of Analysis).
A3: 1. PSA 2024 bank usage rate (61%) applied as uniform proxy across all corridors
A4: 2. National grand totals used as Share denominators (sourced from BSP validated figures, Step 2 of cleaning log)

Sheet BSP_CORRIDORS
A1: Year | B1: Rank | C1: Country | D1: Total_USD_000s | E1: Landbased_USD_000s | F1: Seabased_USD_000s
A2: 2019 | B2: 1 | C2: United States of America | D2: 11318335 | E2: 8815927 | F2: 2502408
A3: 2019 | B3: 2 | C3: Saudi Arabia | D3: 2098287 | E3: 2094386 | F3: 3902
A4: 2019 | B4: 3 | C4: Singapore | D4: 1906494 | E4: 1224036 | F4: 682459
A5: 2019 | B5: 4 | C5: Japan | D5: 1795383 | E5: 1295078 | F5: 500305
A6: 2019 | B6: 5 | C6: United Arab Emirates | D6: 1592453 | E6: 1557433 | F6: 35020
A7: 2019 | B7: 6 | C7: United Kingdom | D7: 1566958 | E7: 1244599 | F7: 322358
A8: 2019 | B8: 7 | C8: Canada | D8: 1015805 | E8: 982539 | F8: 33265
A9: 2019 | B9: 8 | C9: Hong Kong, SAR China | D9: 801749 | E9: 599326 | F9: 202423
A10: 2019 | B10: 9 | C10: Germany | D10: 762304 | E10: 218559 | F10: 543745
A11: 2019 | B11: 10 | C11: Kuwait | D11: 759081 | E11: 755544 | F11: 3536
A12: 2019 | B12: 11 | C12: Qatar | D12: 758136 | E12: 756374 | F12: 1762
A13: 2019 | B13: 12 | C13: Korea (South) | D13: 683211 | E13: 601339 | F13: 81873
... A161: 2024 | B161: 27 | C161: Israel | D161: 106411 | E161: 106256 | F161: 155

Sheet PIVOT_TABLES
A1: Pivot 1: Top 10 Corridors by 2024 Volume
A2: Country | B2: SUM of 2024
A3: Australia | B3: 307064
A4: Bahrain | B4: 261458
A5: Canada | B5: 1230773
A6: Cyprus | B6: 394866
A7: Germany | B7: 622561
A8: Greece | B8: 302922
A9: Hong Kong, SAR China | B9: 801831
A10: Israel | B10: 106411
A11: Italy | B11: 155782
A12: Japan | B12: 1706720
A13: Korea (South) | B13: 853749
A14: Kuwait | B14: 587166
... A30: Grand Total | B30: 33423472
A33: Pivot 2: Top 10 6-Year Cumulative Total
A34: Country | B34: SUM of 6YR_Total
A35: Australia | B35: 1946481
A36: Bahrain | B36: 1538835
A37: Canada | B37: 6804029
A38: Cyprus | B38: 2053316
A39: Germany | B39: 3780030
A40: Greece | B40: 1564819
A41: Hong Kong, SAR China | B41: 4643631
A42: Israel | B42: 445986
A43: Italy | B43: 1022634
A44: Japan | B44: 10019523
A45: Korea (South) | B45: 4679239
A46: Kuwait | B46: 3685289
... A62: Grand Total | B62: 184804053
A65: Pivot 3: COVID Impact Table
A67: Country | B67: SUM of 2019 | C67: SUM of 2020 | D67: SUM of 2021
A68: Australia | B68: 442309 | C68: 319129 | D68: 284924
A69: Bahrain | B69: 323033 | C69: 228554 | D69: 225890
A70: Canada | B70: 1015805 | C70: 1028866 | D70: 1147796
A71: Cyprus | B71: 196902 | C71: 321256 | D71: 364133
A72: Germany | B72: 762304 | C72: 585962 | D72: 609108
A73: Greece | B73: 152742 | C73: 227187 | D73: 296023
A74: Hong Kong, SAR China | B74: 801749 | C74: 821160 | D74: 722229
A75: Israel | B75: 0 | C75: 0 | D75: 119837
...
